Workbook

Sheet Summary Visuals

Sheet Agent Breakdown
A1: Agent Name | B1: Contacts Reviewed | C1: Dead Air | D1: Fillers/Punctuation | E1: First Contact Resolution | F1: Handle Time | G1: Total Opps | H1: % Opps
A2: {=_xlfn.UNIQUE(_xlfn._TRO_TRAILING('April Cleaned Data'!E2:E552))} -> Anderson, Henry | B2: =COUNTIF('April Cleaned Data'!E:E,'Agent Breakdown'!A2) -> 5 | C2: =COUNTIFS('April Cleaned Data'!$E:$E, $A2, 'April Cleaned Data'!$J:$J, "*"&$C$1&"*") -> 1 | D2: =COUNTIFS('April Cleaned Data'!$E:$E, $A2, 'April Cleaned Data'!$J:$J, "*"&$D$1&"*") -> 1 | E2: =COUNTIFS('April Cleaned Data'!$E:$E, $A2, 'April Cleaned Data'!$J:$J, "*"&$E$1&"*") -> 2 | F2: =COUNTIFS('April Cleaned Data'!$E:$E, $A2, 'April Cleaned Data'!$J:$J, "*"&$F$1&"*") -> 1 | G2: =SUM(C2:F2) -> 5 | H2: =IFERROR(G2/B2, 0) -> 1
A3: Brown, Emma | B3: =COUNTIF('April Cleaned Data'!E:E,'Agent Breakdown'!A3) -> 4 | C3: =COUNTIFS('April Cleaned Data'!$E:$E, $A3, 'April Cleaned Data'!$J:$J, "*"&$C$1&"*") -> 1 | D3: =COUNTIFS('April Cleaned Data'!$E:$E, $A3, 'April Cleaned Data'!$J:$J, "*"&$D$1&"*") -> 2 | E3: =COUNTIFS('April Cleaned Data'!$E:$E, $A3, 'April Cleaned Data'!$J:$J, "*"&$E$1&"*") -> 2 | F3: =COUNTIFS('April Cleaned Data'!$E:$E, $A3, 'April Cleaned Data'!$J:$J, "*"&$F$1&"*") -> 0 | G3: =SUM(C3:F3) -> 5 | H3: =IFERROR(G3/B3, 0) -> 1.25
A4: Davis, Charlotte | B4: =COUNTIF('April Cleaned Data'!E:E,'Agent Breakdown'!A4) -> 2 | C4: =COUNTIFS('April Cleaned Data'!$E:$E, $A4, 'April Cleaned Data'!$J:$J, "*"&$C$1&"*") -> 1 | D4: =COUNTIFS('April Cleaned Data'!$E:$E, $A4, 'April Cleaned Data'!$J:$J, "*"&$D$1&"*") -> 0 | E4: =COUNTIFS('April Cleaned Data'!$E:$E, $A4, 'April Cleaned Data'!$J:$J, "*"&$E$1&"*") -> 1 | F4: =COUNTIFS('April Cleaned Data'!$E:$E, $A4, 'April Cleaned Data'!$J:$J, "*"&$F$1&"*") -> 0 | G4: =SUM(C4:F4) -> 2 | H4: =IFERROR(G4/B4, 0) -> 1
A5: Garcia, Ava | B5: =COUNTIF('April Cleaned Data'!E:E,'Agent Breakdown'!A5) -> 1 | C5: =COUNTIFS('April Cleaned Data'!$E:$E, $A5, 'April Cleaned Data'!$J:$J, "*"&$C$1&"*") -> 1 | D5: =COUNTIFS('April Cleaned Data'!$E:$E, $A5, 'April Cleaned Data'!$J:$J, "*"&$D$1&"*") -> 0 | E5: =COUNTIFS('April Cleaned Data'!$E:$E, $A5, 'April Cleaned Data'!$J:$J, "*"&$E$1&"*") -> 0 | F5: =COUNTIFS('April Cleaned Data'!$E:$E, $A5, 'April Cleaned Data'!$J:$J, "*"&$F$1&"*") -> 0 | G5: =SUM(C5:F5) -> 1 | H5: =IFERROR(G5/B5, 0) -> 1
A6: Gonzalez, Lucas | B6: =COUNTIF('April Cleaned Data'!E:E,'Agent Breakdown'!A6) -> 3 | C6: =COUNTIFS('April Cleaned Data'!$E:$E, $A6, 'April Cleaned Data'!$J:$J, "*"&$C$1&"*") -> 1 | D6: =COUNTIFS('April Cleaned Data'!$E:$E, $A6, 'April Cleaned Data'!$J:$J, "*"&$D$1&"*") -> 0 | E6: =COUNTIFS('April Cleaned Data'!$E:$E, $A6, 'April Cleaned Data'!$J:$J, "*"&$E$1&"*") -> 1 | F6: =COUNTIFS('April Cleaned Data'!$E:$E, $A6, 'April Cleaned Data'!$J:$J, "*"&$F$1&"*") -> 0 | G6: =SUM(C6:F6) -> 2 | H6: =IFERROR(G6/B6, 0) -> 0.66666667
A7: Hernandez, Amelia | B7: =COUNTIF('April Cleaned Data'!E:E,'Agent Breakdown'!A7) -> 1 | C7: =COUNTIFS('April Cleaned Data'!$E:$E, $A7, 'April Cleaned Data'!$J:$J, "*"&$C$1&"*") -> 0 | D7: =COUNTIFS('April Cleaned Data'!$E:$E, $A7, 'April Cleaned Data'!$J:$J, "*"&$D$1&"*") -> 0 | E7: =COUNTIFS('April Cleaned Data'!$E:$E, $A7, 'April Cleaned Data'!$J:$J, "*"&$E$1&"*") -> 0 | F7: =COUNTIFS('April Cleaned Data'!$E:$E, $A7, 'April Cleaned Data'!$J:$J, "*"&$F$1&"*") -> 0 | G7: =SUM(C7:F7) -> 0 | H7: =IFERROR(G7/B7, 0) -> 0
A8: Hernandez, Benjamin | B8: =COUNTIF('April Cleaned Data'!E:E,'Agent Breakdown'!A8) -> 1 | C8: =COUNTIFS('April Cleaned Data'!$E:$E, $A8, 'April Cleaned Data'!$J:$J, "*"&$C$1&"*") -> 0 | D8: =COUNTIFS('April Cleaned Data'!$E:$E, $A8, 'April Cleaned Data'!$J:$J, "*"&$D$1&"*") -> 0 | E8: =COUNTIFS('April Cleaned Data'!$E:$E, $A8, 'April Cleaned Data'!$J:$J, "*"&$E$1&"*") -> 0 | F8: =COUNTIFS('April Cleaned Data'!$E:$E, $A8, 'April Cleaned Data'!$J:$J, "*"&$F$1&"*") -> 0 | G8: =SUM(C8:F8) -> 0 | H8: =IFERROR(G8/B8, 0) -> 0
A9: Hernandez, James | B9: =COUNTIF('April Cleaned Data'!E:E,'Agent Breakdown'!A9) -> 1 | C9: =COUNTIFS('April Cleaned Data'!$E:$E, $A9, 'April Cleaned Data'!$J:$J, "*"&$C$1&"*") -> 0 | D9: =COUNTIFS('April Cleaned Data'!$E:$E, $A9, 'April Cleaned Data'!$J:$J, "*"&$D$1&"*") -> 0 | E9: =COUNTIFS('April Cleaned Data'!$E:$E, $A9, 'April Cleaned Data'!$J:$J, "*"&$E$1&"*") -> 0 | F9: =COUNTIFS('April Cleaned Data'!$E:$E, $A9, 'April Cleaned Data'!$J:$J, "*"&$F$1&"*") -> 0 | G9: =SUM(C9:F9) -> 0 | H9: =IFERROR(G9/B9, 0) -> 0
A10: Jackson, Mason | B10: =COUNTIF('April Cleaned Data'!E:E,'Agent Breakdown'!A10) -> 2 | C10: =COUNTIFS('April Cleaned Data'!$E:$E, $A10, 'April Cleaned Data'!$J:$J, "*"&$C$1&"*") -> 0 | D10: =COUNTIFS('April Cleaned Data'!$E:$E, $A10, 'April Cleaned Data'!$J:$J, "*"&$D$1&"*") -> 0 | E10: =COUNTIFS('April Cleaned Data'!$E:$E, $A10, 'April Cleaned Data'!$J:$J, "*"&$E$1&"*") -> 1 | F10: =COUNTIFS('April Cleaned Data'!$E:$E, $A10, 'April Cleaned Data'!$J:$J, "*"&$F$1&"*") -> 0 | G10: =SUM(C10:F10) -> 1 | H10: =IFERROR(G10/B10, 0) -> 0.5
A11: Johnson, Olivia | B11: =COUNTIF('April Cleaned Data'!E:E,'Agent Breakdown'!A11) -> 1 | C11: =COUNTIFS('April Cleaned Data'!$E:$E, $A11, 'April Cleaned Data'!$J:$J, "*"&$C$1&"*") -> 0 | D11: =COUNTIFS('April Cleaned Data'!$E:$E, $A11, 'April Cleaned Data'!$J:$J, "*"&$D$1&"*") -> 0 | E11: =COUNTIFS('April Cleaned Data'!$E:$E, $A11, 'April Cleaned Data'!$J:$J, "*"&$E$1&"*") -> 0 | F11: =COUNTIFS('April Cleaned Data'!$E:$E, $A11, 'April Cleaned Data'!$J:$J, "*"&$F$1&"*") -> 1 | G11: =SUM(C11:F11) -> 1 | H11: =IFERROR(G11/B11, 0) -> 1
A12: Jones, Oliver | B12: =COUNTIF('April Cleaned Data'!E:E,'Agent Breakdown'!A12) -> 1 | C12: =COUNTIFS('April Cleaned Data'!$E:$E, $A12, 'April Cleaned Data'!$J:$J, "*"&$C$1&"*") -> 1 | D12: =COUNTIFS('April Cleaned Data'!$E:$E, $A12, 'April Cleaned Data'!$J:$J, "*"&$D$1&"*") -> 1 | E12: =COUNTIFS('April Cleaned Data'!$E:$E, $A12, 'April Cleaned Data'!$J:$J, "*"&$E$1&"*") -> 0 | F12: =COUNTIFS('April Cleaned Data'!$E:$E, $A12, 'April Cleaned Data'!$J:$J, "*"&$F$1&"*") -> 0 | G12: =SUM(C12:F12) -> 2 | H12: =IFERROR(G12/B12, 0) -> 2
A13: Lee, Michael | B13: =COUNTIF('April Cleaned Data'!E:E,'Agent Breakdown'!A13) -> 3 | C13: =COUNTIFS('April Cleaned Data'!$E:$E, $A13, 'April Cleaned Data'!$J:$J, "*"&$C$1&"*") -> 2 | D13: =COUNTIFS('April Cleaned Data'!$E:$E, $A13, 'April Cleaned Data'!$J:$J, "*"&$D$1&"*") -> 0 | E13: =COUNTIFS('April Cleaned Data'!$E:$E, $A13, 'April Cleaned Data'!$J:$J, "*"&$E$1&"*") -> 1 | F13: =COUNTIFS('April Cleaned Data'!$E:$E, $A13, 'April Cleaned Data'!$J:$J, "*"&$F$1&"*") -> 1 | G13: =SUM(C13:F13) -> 4 | H13: =IFERROR(G13/B13, 0) -> 1.3333333
A14: Lee, Sophia | B14: =COUNTIF('April Cleaned Data'!E:E,'Agent Breakdown'!A14) -> 1 | C14: =COUNTIFS('April Cleaned Data'!$E:$E, $A14, 'April Cleaned Data'!$J:$J, "*"&$C$1&"*") -> 1 | D14: =COUNTIFS('April Cleaned Data'!$E:$E, $A14, 'April Cleaned Data'!$J:$J, "*"&$D$1&"*") -> 0 | E14: =COUNTIFS('April Cleaned Data'!$E:$E, $A14, 'April Cleaned Data'!$J:$J, "*"&$E$1&"*") -> 0 | F14: =COUNTIFS('April Cleaned Data'!$E:$E, $A14, 'April Cleaned Data'!$J:$J, "*"&$F$1&"*") -> 0 | G14: =SUM(C14:F14) -> 1 | H14: =IFERROR(G14/B14, 0) -> 1
... A26: Wilson, Mia | B26: =COUNTIF('April Cleaned Data'!E:E,'Agent Breakdown'!A26) -> 1 | C26: =COUNTIFS('April Cleaned Data'!$E:$E, $A26, 'April Cleaned Data'!$J:$J, "*"&$C$1&"*") -> 0 | D26: =COUNTIFS('April Cleaned Data'!$E:$E, $A26, 'April Cleaned Data'!$J:$J, "*"&$D$1&"*") -> 0 | E26: =COUNTIFS('April Cleaned Data'!$E:$E, $A26, 'April Cleaned Data'!$J:$J, "*"&$E$1&"*") -> 1 | F26: =COUNTIFS('April Cleaned Data'!$E:$E, $A26, 'April Cleaned Data'!$J:$J, "*"&$F$1&"*") -> 0 | G26: =SUM(C26:F26) -> 1 | H26: =IFERROR(G26/B26, 0) -> 1
B27: =COUNTIF('April Cleaned Data'!E:E,'Agent Breakdown'!A27) -> 0 | C27: =COUNTIFS('April Cleaned Data'!$E:$E, $A27, 'April Cleaned Data'!$J:$J, "*"&$C$1&"*") -> 0 | D27: =COUNTIFS('April Cleaned Data'!$E:$E, $A27, 'April Cleaned Data'!$J:$J, "*"&$D$1&"*") -> 0 | E27: =COUNTIFS('April Cleaned Data'!$E:$E, $A27, 'April Cleaned Data'!$J:$J, "*"&$E$1&"*") -> 0 | F27: =COUNTIFS('April Cleaned Data'!$E:$E, $A27, 'April Cleaned Data'!$J:$J, "*"&$F$1&"*") -> 0 | G27: =SUM(C27:F27) -> 0 | H27: =IFERROR(G27/B27, 0) -> 0
B28: =COUNTIF('April Cleaned Data'!E:E,'Agent Breakdown'!A28) -> 0 | C28: =COUNTIFS('April Cleaned Data'!$E:$E, $A28, 'April Cleaned Data'!$J:$J, "*"&$C$1&"*") -> 0 | D28: =COUNTIFS('April Cleaned Data'!$E:$E, $A28, 'April Cleaned Data'!$J:$J, "*"&$D$1&"*") -> 0 | E28: =COUNTIFS('April Cleaned Data'!$E:$E, $A28, 'April Cleaned Data'!$J:$J, "*"&$E$1&"*") -> 0 | F28: =COUNTIFS('April Cleaned Data'!$E:$E, $A28, 'April Cleaned Data'!$J:$J, "*"&$F$1&"*") -> 0 | G28: =SUM(C28:F28) -> 0 | H28: =IFERROR(G28/B28, 0) -> 0
B29: =COUNTIF('April Cleaned Data'!E:E,'Agent Breakdown'!A29) -> 0 | C29: =COUNTIFS('April Cleaned Data'!$E:$E, $A29, 'April Cleaned Data'!$J:$J, "*"&$C$1&"*") -> 0 | D29: =COUNTIFS('April Cleaned Data'!$E:$E, $A29, 'April Cleaned Data'!$J:$J, "*"&$D$1&"*") -> 0 | E29: =COUNTIFS('April Cleaned Data'!$E:$E, $A29, 'April Cleaned Data'!$J:$J, "*"&$E$1&"*") -> 0 | F29: =COUNTIFS('April Cleaned Data'!$E:$E, $A29, 'April Cleaned Data'!$J:$J, "*"&$F$1&"*") -> 0 | G29: =SUM(C29:F29) -> 0 | H29: =IFERROR(G29/B29, 0) -> 0
B30: =COUNTIF('April Cleaned Data'!E:E,'Agent Breakdown'!A30) -> 0 | C30: =COUNTIFS('April Cleaned Data'!$E:$E, $A30, 'April Cleaned Data'!$J:$J, "*"&$C$1&"*") -> 0 | D30: =COUNTIFS('April Cleaned Data'!$E:$E, $A30, 'April Cleaned Data'!$J:$J, "*"&$D$1&"*") -> 0 | E30: =COUNTIFS('April Cleaned Data'!$E:$E, $A30, 'April Cleaned Data'!$J:$J, "*"&$E$1&"*") -> 0 | F30: =COUNTIFS('April Cleaned Data'!$E:$E, $A30, 'April Cleaned Data'!$J:$J, "*"&$F$1&"*") -> 0 | G30: =SUM(C30:F30) -> 0 | H30: =IFERROR(G30/B30, 0) -> 0
B31: =COUNTIF('April Cleaned Data'!E:E,'Agent Breakdown'!A31) -> 0 | C31: =COUNTIFS('April Cleaned Data'!$E:$E, $A31, 'April Cleaned Data'!$J:$J, "*"&$C$1&"*") -> 0 | D31: =COUNTIFS('April Cleaned Data'!$E:$E, $A31, 'April Cleaned Data'!$J:$J, "*"&$D$1&"*") -> 0 | E31: =COUNTIFS('April Cleaned Data'!$E:$E, $A31, 'April Cleaned Data'!$J:$J, "*"&$E$1&"*") -> 0 | F31: =COUNTIFS('April Cleaned Data'!$E:$E, $A31, 'April Cleaned Data'!$J:$J, "*"&$F$1&"*") -> 0 | G31: =SUM(C31:F31) -> 0 | H31: =IFERROR(G31/B31, 0) -> 0
B32: =COUNTIF('April Cleaned Data'!E:E,'Agent Breakdown'!A32) -> 0 | C32: =COUNTIFS('April Cleaned Data'!$E:$E, $A32, 'April Cleaned Data'!$J:$J, "*"&$C$1&"*") -> 0 | D32: =COUNTIFS('April Cleaned Data'!$E:$E, $A32, 'April Cleaned Data'!$J:$J, "*"&$D$1&"*") -> 0 | E32: =COUNTIFS('April Cleaned Data'!$E:$E, $A32, 'April Cleaned Data'!$J:$J, "*"&$E$1&"*") -> 0 | F32: =COUNTIFS('April Cleaned Data'!$E:$E, $A32, 'April Cleaned Data'!$J:$J, "*"&$F$1&"*") -> 0 | G32: =SUM(C32:F32) -> 0 | H32: =IFERROR(G32/B32, 0) -> 0
B33: =COUNTIF('April Cleaned Data'!E:E,'Agent Breakdown'!A33) -> 0 | C33: =COUNTIFS('April Cleaned Data'!$E:$E, $A33, 'April Cleaned Data'!$J:$J, "*"&$C$1&"*") -> 0 | D33: =COUNTIFS('April Cleaned Data'!$E:$E, $A33, 'April Cleaned Data'!$J:$J, "*"&$D$1&"*") -> 0 | E33: =COUNTIFS('April Cleaned Data'!$E:$E, $A33, 'April Cleaned Data'!$J:$J, "*"&$E$1&"*") -> 0 | F33: =COUNTIFS('April Cleaned Data'!$E:$E, $A33, 'April Cleaned Data'!$J:$J, "*"&$F$1&"*") -> 0 | G33: =SUM(C33:F33) -> 0 | H33: =IFERROR(G33/B33, 0) -> 0
B34: =COUNTIF('April Cleaned Data'!E:E,'Agent Breakdown'!A34) -> 0 | C34: =COUNTIFS('April Cleaned Data'!$E:$E, $A34, 'April Cleaned Data'!$J:$J, "*"&$C$1&"*") -> 0 | D34: =COUNTIFS('April Cleaned Data'!$E:$E, $A34, 'April Cleaned Data'!$J:$J, "*"&$D$1&"*") -> 0 | E34: =COUNTIFS('April Cleaned Data'!$E:$E, $A34, 'April Cleaned Data'!$J:$J, "*"&$E$1&"*") -> 0 | F34: =COUNTIFS('April Cleaned Data'!$E:$E, $A34, 'April Cleaned Data'!$J:$J, "*"&$F$1&"*") -> 0 | G34: =SUM(C34:F34) -> 0 | H34: =IFERROR(G34/B34, 0) -> 0
B35: =COUNTIF('April Cleaned Data'!E:E,'Agent Breakdown'!A35) -> 0 | C35: =COUNTIFS('April Cleaned Data'!$E:$E, $A35, 'April Cleaned Data'!$J:$J, "*"&$C$1&"*") -> 0 | D35: =COUNTIFS('April Cleaned Data'!$E:$E, $A35, 'April Cleaned Data'!$J:$J, "*"&$D$1&"*") -> 0 | E35: =COUNTIFS('April Cleaned Data'!$E:$E, $A35, 'April Cleaned Data'!$J:$J, "*"&$E$1&"*") -> 0 | F35: =COUNTIFS('April Cleaned Data'!$E:$E, $A35, 'April Cleaned Data'!$J:$J, "*"&$F$1&"*") -> 0 | G35: =SUM(C35:F35) -> 0 | H35: =IFERROR(G35/B35, 0) -> 0
B36: =COUNTIF('April Cleaned Data'!E:E,'Agent Breakdown'!A36) -> 0 | C36: =COUNTIFS('April Cleaned Data'!$E:$E, $A36, 'April Cleaned Data'!$J:$J, "*"&$C$1&"*") -> 0 | D36: =COUNTIFS('April Cleaned Data'!$E:$E, $A36, 'April Cleaned Data'!$J:$J, "*"&$D$1&"*") -> 0 | E36: =COUNTIFS('April Cleaned Data'!$E:$E, $A36, 'April Cleaned Data'!$J:$J, "*"&$E$1&"*") -> 0 | F36: =COUNTIFS('April Cleaned Data'!$E:$E, $A36, 'April Cleaned Data'!$J:$J, "*"&$F$1&"*") -> 0 | G36: =SUM(C36:F36) -> 0 | H36: =IFERROR(G36/B36, 0) -> 0
B37: =COUNTIF('April Cleaned Data'!E:E,'Agent Breakdown'!A37) -> 0 | C37: =COUNTIFS('April Cleaned Data'!$E:$E, $A37, 'April Cleaned Data'!$J:$J, "*"&$C$1&"*") -> 0 | D37: =COUNTIFS('April Cleaned Data'!$E:$E, $A37, 'April Cleaned Data'!$J:$J, "*"&$D$1&"*") -> 0 | E37: =COUNTIFS('April Cleaned Data'!$E:$E, $A37, 'April Cleaned Data'!$J:$J, "*"&$E$1&"*") -> 0 | F37: =COUNTIFS('April Cleaned Data'!$E:$E, $A37, 'April Cleaned Data'!$J:$J, "*"&$F$1&"*") -> 0 | G37: =SUM(C37:F37) -> 0 | H37: =IFERROR(G37/B37, 0) -> 0
B38: =COUNTIF('April Cleaned Data'!E:E,'Agent Breakdown'!A38) -> 0 | C38: =COUNTIFS('April Cleaned Data'!$E:$E, $A38, 'April Cleaned Data'!$J:$J, "*"&$C$1&"*") -> 0 | D38: =COUNTIFS('April Cleaned Data'!$E:$E, $A38, 'April Cleaned Data'!$J:$J, "*"&$D$1&"*") -> 0 | E38: =COUNTIFS('April Cleaned Data'!$E:$E, $A38, 'April Cleaned Data'!$J:$J, "*"&$E$1&"*") -> 0 | F38: =COUNTIFS('April Cleaned Data'!$E:$E, $A38, 'April Cleaned Data'!$J:$J, "*"&$F$1&"*") -> 0 | G38: =SUM(C38:F38) -> 0 | H38: =IFERROR(G38/B38, 0) -> 0
... B50: =COUNTIF('April Cleaned Data'!E:E,'Agent Breakdown'!A50) -> 0 | C50: =COUNTIFS('April Cleaned Data'!$E:$E, $A50, 'April Cleaned Data'!$J:$J, "*"&$C$1&"*") -> 0 | D50: =COUNTIFS('April Cleaned Data'!$E:$E, $A50, 'April Cleaned Data'!$J:$J, "*"&$D$1&"*") -> 0 | E50: =COUNTIFS('April Cleaned Data'!$E:$E, $A50, 'April Cleaned Data'!$J:$J, "*"&$E$1&"*") -> 0 | F50: =COUNTIFS('April Cleaned Data'!$E:$E, $A50, 'April Cleaned Data'!$J:$J, "*"&$F$1&"*") -> 0 | G50: =SUM(C50:F50) -> 0 | H50: =IFERROR(G50/B50, 0) -> 0

Sheet Supervisor Sheet
A1: Supervisor | B1: Agent Name | C1: Date | D1: Channel | E1: Contact ID | F1: Order# | G1: Contact Notes | H1: Opportunities
A2: =_xlfn.XLOOKUP(B2, AgentSupervisorList!C:C, AgentSupervisorList!D:D) -> Blackwood, Seraphina | B2: Gonzalez, Lucas | C2: 43934 | D2: Email | E2: 1259 | F2: 11147 | G2: An email came in requesting a refund for a damaged dress. Lucas sent a generic macro response that completely ignored the attached photo proof, requiring the customer to email back in annoyance. | H2: First Contact Resolution
A3: =_xlfn.XLOOKUP(B3, AgentSupervisorList!C:C, AgentSupervisorList!D:D) -> Blackwood, Seraphina | B3: Gonzalez, Lucas | C3: 43937 | D3: Chat | E3: 27-32257 | F3: 11157 | G3: The customer asked a simple question about return windows. Lucas took over 4 minutes to type each basic response, leading the customer to ask if anyone was still there. | H3: Dead Air
A4: =_xlfn.XLOOKUP(B4, AgentSupervisorList!C:C, AgentSupervisorList!D:D) -> Blackwood, Seraphina | B4: Gonzalez, Lucas | C4: 43944 | D4: Chat | E4: 27-32153 | G4: Customer wants to know why they can't process their order. After asking several probing questions, the agent determined the customer was entering the wrong number as the CVV.
A5: =_xlfn.XLOOKUP(B5, AgentSupervisorList!C:C, AgentSupervisorList!D:D) -> Blackwood, Seraphina | B5: Hernandez, Benjamin | C5: 43926 | D5: Email | E5: 1245 | F5: 11005 | G5: Customer wrote in to advise their zipper is broken after one use. The agent apologized, went over return process, and sent label.
A6: =_xlfn.XLOOKUP(B6, AgentSupervisorList!C:C, AgentSupervisorList!D:D) -> Blackwood, Seraphina | B6: Lopez, Isabella | C6: 43928 | D6: Phone | E6: AD12444 | F6: 11150 | G6: The customer called in to try to place an order over the phone. The agent walked the customer through the ordering process. Agent thanked the customer for calling, but forgot to give the ending script. The customer did not hang up, so after a couple minutes the agent provided the disconnect script and ended the call. | H6: Scripting/Templates, Dead Air
A7: =_xlfn.XLOOKUP(B7, AgentSupervisorList!C:C, AgentSupervisorList!D:D) -> Blackwood, Seraphina | B7: Lopez, Isabella | C7: 43937 | D7: Chat | E7: 27-32258 | F7: 11151 | G7: The shopper’s tracking number hadn't updated in 5 days. Isabella quickly opened an investigation with the carrier and proactively set up a text alert to keep the customer updated. | H7: Handle Time
A8: =_xlfn.XLOOKUP(B8, AgentSupervisorList!C:C, AgentSupervisorList!D:D) -> Blackwood, Seraphina | B8: Lopez, Isabella | C8: 43942 | D8: Chat | E8: 27-32265 | F8: 11173 | G8: A customer received a pair of shoes with two different sizes. Isabella apologized for the warehouse mix-up, sent out the correct pair via express shipping, and told the customer to donate the mismatched pair. | H8: Fillers/Punctuation
A9: =_xlfn.XLOOKUP(B9, AgentSupervisorList!C:C, AgentSupervisorList!D:D) -> Blackwood, Seraphina | B9: Martinez, Sophia | C9: 43934 | D9: Email | E9: 1260 | F9: 11140 | G9: A bulk-order customer requested a custom invoice format for their corporate event clothing. Sophia coordinated with billing and delivered the exact breakdown requested. | H9: Handle Time
A10: =_xlfn.XLOOKUP(B10, AgentSupervisorList!C:C, AgentSupervisorList!D:D) -> Blackwood, Seraphina | B10: Martinez, Sophia | C10: 43935 | D10: Phone | E10: AD12540 | F10: 11102 | G10: The caller was highly irate about a major shipping delay. Sophia accidentally interrupted the customer mid-sentence to quote policy, which caused the customer to escalate the call to a manager. | H10: First Contact Resolution
A11: =_xlfn.XLOOKUP(B11, AgentSupervisorList!C:C, AgentSupervisorList!D:D) -> Blackwood, Seraphina | B11: Martinez, Sophia | C11: 43951 | D11: Phone | E11: AD12447 | G11: The customer called in to complain about previous service. They've called several times for various issues and has never had a happy experience. Most recently, they got a coupon they couldn't use and the replacement coupon didn't work. The agent seemed nervous and stammered a lot during the conversation, which made the customer escalate and ask for a Supervisor. Agent transferred to a Specialist. | H11: Fillers/Punctuation
A12: =_xlfn.XLOOKUP(B12, AgentSupervisorList!C:C, AgentSupervisorList!D:D) -> Blackwood, Seraphina | B12: Rodriguez, William | C12: 43930 | D12: Phone | E12: AD12450 | F12: 11148 | G12: Standard WIZMO call. No notes for agent.
A13: =_xlfn.XLOOKUP(B13, AgentSupervisorList!C:C, AgentSupervisorList!D:D) -> Blackwood, Seraphina | B13: Rodriguez, William | C13: 43950 | D13: Chat | E13: 27-32262 | G13: A customer reached out on behalf of their teenager to find a trending jacket. William found a hidden restock in the inventory log and reserved it for them. | H13: Dead Air, Fillers/Punctuation, First Contact Resolution
A14: =_xlfn.XLOOKUP(B14, AgentSupervisorList!C:C, AgentSupervisorList!D:D) -> Finch, Cordelia | B14: Jackson, Mason | C14: 43944 | D14: Email | E14: 1247 | G14: Customer wrote in angrily because the coupon code they tried using was not working. The agent aplogized and asked them to reply with the code they were attempting to use. | H14: Scripting/Templates
A15: =_xlfn.XLOOKUP(B15, AgentSupervisorList!C:C, AgentSupervisorList!D:D) -> Finch, Cordelia | B15: Jackson, Mason | C15: 43941 | D15: Chat | E15: 27-32264 | G15: The customer asked if a specific material contained wool due to a severe allergy. Mason guessed "no" without checking the product spec sheet, creating a major safety risk. | H15: First Contact Resolution
A16: =_xlfn.XLOOKUP(B16, AgentSupervisorList!C:C, AgentSupervisorList!D:D) -> Finch, Cordelia | B16: Lee, Michael | C16: 43927 | D16: Phone | E16: AD12442 | F16: 11120 | G16: Customer called because their order was marked as delivered, but they didn't recieve it. The agent checked the tracking, confirmed it was delivered over two days ago, and offered to reship overnight. The customer agreed.
A17: =_xlfn.XLOOKUP(B17, AgentSupervisorList!C:C, AgentSupervisorList!D:D) -> Finch, Cordelia | B17: Lee, Michael | C17: 43943 | D17: Chat | E17: 27-32267 | G17: A customer couldn't find where to enter a gift card code on a mobile browser. Michael took a quick screenshot, circled the field, and sent it over, resolving the issue instantly. | H17: Dead Air
A18: =_xlfn.XLOOKUP(B18, AgentSupervisorList!C:C, AgentSupervisorList!D:D) -> Finch, Cordelia | B18: Lee, Michael | C18: 43936 | D18: Phone | E18: AD12543 | F18: 11153 | G18: The customer called about a double-billing error. Michael put the customer on hold for over 10 minutes without checking back in, leading to a frustrated hang-up. | H18: Dead Air, First Contact Resolution, Handle Time
A19: =_xlfn.XLOOKUP(B19, AgentSupervisorList!C:C, AgentSupervisorList!D:D) -> Finch, Cordelia | B19: Martin, Camila | C19: 43928 | D19: Phone | E19: AD12445 | F19: 11111 | G19: The customer contacted to initiate a return for a shirt that she didn't love - did not elaborate why. The agent explained the return process and provided the return label. | H19: Fillers/Punctuation
A20: =_xlfn.XLOOKUP(B20, AgentSupervisorList!C:C, AgentSupervisorList!D:D) -> Finch, Cordelia | B20: Martin, Camila | C20: 43949 | D20: Phone | E20: AD12446 | G20: The customer is calling back to talk to a Specialist regarding a complaint she wanted to make about the website. The agent put the customer on hold to transfer her over. | H20: Fillers/Punctuation
A21: =_xlfn.XLOOKUP(B21, AgentSupervisorList!C:C, AgentSupervisorList!D:D) -> Finch, Cordelia | B21: Martinez, Bill | C21: 43936 | D21: Phone | E21: AD12545 | G21: The customer called to report a broken website link on a major promotion page. Agentvalidated the issue, reported it immediately to IT, and manually applied the promo price for the caller. | H21: Handle Time
A22: =_xlfn.XLOOKUP(B22, AgentSupervisorList!C:C, AgentSupervisorList!D:D) -> Finch, Cordelia | B22: Martinez, Bill | C22: 43948 | D22: Chat | E22: 27-32259 | F22: 11205 | G22: A customer wanted to cancel an order placed 5 minutes prior. Bill acted instantly, canceling the order before it hit fulfillment and saving the customer return shipping fees. | H22: Scripting/Templates
A23: =_xlfn.XLOOKUP(B23, AgentSupervisorList!C:C, AgentSupervisorList!D:D) -> Finch, Cordelia | B23: Moore, Harper | C23: 43929 | D23: Phone | E23: AD12449 | F23: 11151 | G23: Customer called because her address is incorrect on her order. She put the wrong house number on the address. The agent apologized, checked the tracking, noted it hasn't left the facility left, and issued a ticket to the carrier to update the address. | H23: Handle Time
A24: =_xlfn.XLOOKUP(B24, AgentSupervisorList!C:C, AgentSupervisorList!D:D) -> Mercer, Gideon | B24: Anderson, Henry | C24: 43923 | D24: Phone | E24: AD12434 | F24: 110025 | G24: Customer called to track order. Agent checked order, provided information of wrong order. | H24: Dead Air, First Contact Resolution
A25: =_xlfn.XLOOKUP(B25, AgentSupervisorList!C:C, AgentSupervisorList!D:D) -> Mercer, Gideon | B25: Anderson, Henry | C25: 43933 | D25: Chat | E25: 27-32146 | G25: A shopper asked for sizing recommendations for a specific brand of jeans. Henry looked up the precise measurements and helped them confidently pick the right size. | H25: Handle Time
A26: =_xlfn.XLOOKUP(B26, AgentSupervisorList!C:C, AgentSupervisorList!D:D) -> Mercer, Gideon | B26: Anderson, Henry | C26: 43933 | D26: Chat | E26: 27-32145 | F26: 11155 | G26: A customer was disconnect-looping and frustrated. Henry didn't read the prior notes from the immediate previous chat and made the customer repeat their shipping address issue all over again. Customer ended up disconnecting again. | H26: First Contact Resolution
A27: =_xlfn.XLOOKUP(B27, AgentSupervisorList!C:C, AgentSupervisorList!D:D) -> Mercer, Gideon | B27: Anderson, Henry | C27: 43935 | D27: Phone | E27: AD12541 | F27: 11146 | G27: An elderly customer called confused about how to initiate an online return. Henry remained incredibly warm and patient, staying on the line until the return label was successfully printed.
A28: =_xlfn.XLOOKUP(B28, AgentSupervisorList!C:C, AgentSupervisorList!D:D) -> Mercer, Gideon | B28: Anderson, Henry | C28: 43941 | D28: Chat | E28: 27-32263 | F28: 11163 | G28: The customer's package was stolen from their porch. Henry expressed genuine empathy and authorized a one-time courtesy replacement order to be shipped to a secure pickup location. | H28: Fillers/Punctuation
A29: =_xlfn.XLOOKUP(B29, AgentSupervisorList!C:C, AgentSupervisorList!D:D) -> Mercer, Gideon | B29: Lee, Sophia | C29: 43927 | D29: Phone | E29: AD12443 | F29: 11126 | G29: The customer called to report that their third package has arrived damaged. The agent checked the customer's history, saw repeated communications, and forwarded to a Specialist to handle. | H29: Dead Air
A30: =_xlfn.XLOOKUP(B30, AgentSupervisorList!C:C, AgentSupervisorList!D:D) -> Mercer, Gideon | B30: Taylor, Alexander | C30: 43930 | D30: Phone | E30: AD12452 | F30: 11152/11153 | G30: Customer about a double charge. Agent found two orders were shipped. Customer will return one when both arrive.
A31: =_xlfn.XLOOKUP(B31, AgentSupervisorList!C:C, AgentSupervisorList!D:D) -> Mercer, Gideon | B31: Thomas, Evelyn | C31: 43931 | D31: Chat | E31: 27-32149 | F31: 11114 | G31: The customer reached out to exchange a sweater size. Evelyn processed the return label and applied a courtesy discount for a future purchase, leaving the customer thrilled. | H31: Dead Air, Handle Time
A32: =_xlfn.XLOOKUP(B32, AgentSupervisorList!C:C, AgentSupervisorList!D:D) -> Mercer, Gideon | B32: Thomas, Evelyn | C32: 43937 | D32: Chat | E32: 27-32256 | G32: A customer was looking for a specific outfit style for a family photoshoot. Evelyn acted as a personal stylist, dropping links to coordinating pieces that the customer immediately bought. | H32: Scripting/Templates
A33: =_xlfn.XLOOKUP(B33, AgentSupervisorList!C:C, AgentSupervisorList!D:D) -> Mercer, Gideon | B33: Wilson, Mia | C33: 43933 | D33: Chat | E33: 27-32147 | G33: The customer was frustrated that a clearance item sold out while in their cart. Mia gave rigid, scripted responses without offering alternative items, causing the customer to close the chat abruptly. | H33: First Contact Resolution
A34: =_xlfn.XLOOKUP(B34, AgentSupervisorList!C:C, AgentSupervisorList!D:D) -> Thorne, Alistair | B34: Davis, Charlotte | C34: 43924 | D34: Chat | E34: 27-32155 | G34: Customer chatted in to inquire if we have any shirts in an Orange color. Agent took a long time (2+ minutes) to research without getting back to the customer, but came back and provided a list of shirts that come in Orange. Some of these were discontinued, though. | H34: Dead Air, First Contact Resolution
A35: =_xlfn.XLOOKUP(B35, AgentSupervisorList!C:C, AgentSupervisorList!D:D) -> Thorne, Alistair | B35: Davis, Charlotte | C35: 43936 | D35: Phone | E35: AD12544 | F35: 11170 | G35: A customer called to praise a previous agent but stayed to order more items. Charlotte expertly cross-sold a matching accessory set, increasing the overall order value.
A36: =_xlfn.XLOOKUP(B36, AgentSupervisorList!C:C, AgentSupervisorList!D:D) -> Thorne, Alistair | B36: Garcia, Ava | C36: 43924 | D36: Chat | E36: 27-32154 | G36: Customer chatted in to see if we are hiring. Agent referred to company career site. | H36: Dead Air
A37: =_xlfn.XLOOKUP(B37, AgentSupervisorList!C:C, AgentSupervisorList!D:D) -> Thorne, Alistair | B37: Hernandez, Amelia | C37: 43926 | D37: Email | E37: 1244 | F37: 11118 | G37: Customer emailed to ask where their order is - the tracking information isn't working for them. The agent replied with outdated template to provide tracking information and estimated delivery date. Accurate information was given, however. | H37: Scripting/Templates
A38: =_xlfn.XLOOKUP(B38, AgentSupervisorList!C:C, AgentSupervisorList!D:D) -> Thorne, Alistair | B38: Jones, Oliver | C38: 43927 | D38: Phone | E38: AD12441 | F38: 11127 | G38: The customer called, irate because they felt like they were double-charged for their order. Agent attempted to explain authorization holds, but the customer kept cutting them off and hung up on the agent. | H38: Dead Air, Fillers/Punctuation
A39: =_xlfn.XLOOKUP(B39, AgentSupervisorList!C:C, AgentSupervisorList!D:D) -> Thorne, Alistair | B39: Miller, Elijah | C39: 43938 | D39: Chat | E39: 27-32261 | F39: 11188 | G39: In a back-to-back chat, Elijah mixed up this customer's order details with a previous cancellation request, causing massive confusion for a customer who actually wanted to add an item. Customer had to chat in later to get clarification. | H39: Fillers/Punctuation, First Contact Resolution
A40: =_xlfn.XLOOKUP(B40, AgentSupervisorList!C:C, AgentSupervisorList!D:D) -> Thorne, Alistair | B40: Miller, Elijah | C40: 43943 | D40: Chat | E40: 27-32266 | G40: Elijah took over a transferred chat from Emma but failed to read the active conversation, asking the user "How can I help you today?" which caused the customer further upset, and they requested to speak to a supervisor. | H40: First Contact Resolution
...

Sheet April Cleaned Data
A1: Date | B1: Agent Name | C1: Agent Name_First | D1: Agent Name_Last | E1: Agent Name, Proper | F1: Channel | G1: Contact ID | H1: Order# | I1: Contact Notes | J1: Opportunities
A2: 43923 | B2: Henry Anderson | C2: =_xlfn.TEXTBEFORE(B2,",",,,,_xlfn.TEXTBEFORE(B2," ")) -> Henry | D2: =_xlfn.TEXTAFTER(B2,",",,,,_xlfn.TEXTAFTER(B2," ")) -> Anderson | E2: Anderson, Henry | F2: Phone | G2: AD12434 | H2: 110025 | I2: Customer called to track order. Agent checked order, provided information of wrong order. | J2: Dead Air, First Contact Resolution
A3: 43933 | B3: Anderson, Henry | C3: =_xlfn.TEXTBEFORE(B3,",",,,,_xlfn.TEXTBEFORE(B3," ")) -> Anderson | D3: =_xlfn.TEXTAFTER(B3,",",,,,_xlfn.TEXTAFTER(B3," ")) -> Henry | E3: Anderson, Henry | F3: Chat | G3: 27-32146 | I3: A shopper asked for sizing recommendations for a specific brand of jeans. Henry looked up the precise measurements and helped them confidently pick the right size. | J3: Handle Time
A4: 43933 | B4: Anderson, Henry | C4: =_xlfn.TEXTBEFORE(B4,",",,,,_xlfn.TEXTBEFORE(B4," ")) -> Anderson | D4: =_xlfn.TEXTAFTER(B4,",",,,,_xlfn.TEXTAFTER(B4," ")) -> Henry | E4: Anderson, Henry | F4: Chat | G4: 27-32145 | H4: 11155 | I4: A customer was disconnect-looping and frustrated. Henry didn't read the prior notes from the immediate previous chat and made the customer repeat their shipping address issue all over again. Customer ended up disconnecting again. | J4: First Contact Resolution
A5: 43935 | B5: Anderson, Henry | C5: =_xlfn.TEXTBEFORE(B5,",",,,,_xlfn.TEXTBEFORE(B5," ")) -> Anderson | D5: =_xlfn.TEXTAFTER(B5,",",,,,_xlfn.TEXTAFTER(B5," ")) -> Henry | E5: Anderson, Henry | F5: Phone | G5: AD12541 | H5: 11146 | I5: An elderly customer called confused about how to initiate an online return. Henry remained incredibly warm and patient, staying on the line until the return label was successfully printed.
A6: 43941 | B6: Anderson, Henry | C6: =_xlfn.TEXTBEFORE(B6,",",,,,_xlfn.TEXTBEFORE(B6," ")) -> Anderson | D6: =_xlfn.TEXTAFTER(B6,",",,,,_xlfn.TEXTAFTER(B6," ")) -> Henry | E6: Anderson, Henry | F6: Chat | G6: 27-32263 | H6: 11163 | I6: The customer's package was stolen from their porch. Henry expressed genuine empathy and authorized a one-time courtesy replacement order to be shipped to a secure pickup location. | J6: Fillers/Punctuation
A7: 43923 | B7: Brown, Emma | C7: =_xlfn.TEXTBEFORE(B7,",",,,,_xlfn.TEXTBEFORE(B7," ")) -> Brown | D7: =_xlfn.TEXTAFTER(B7,",",,,,_xlfn.TEXTAFTER(B7," ")) -> Emma | E7: Brown, Emma | F7: Phone | G7: AD12435 | I7: Customer wanted to know if products were ethically sourced. Agent correctly provided information to sourcing.
A8: 43942 | B8: Brown,, Emma | C8: =_xlfn.TEXTBEFORE(B8,",",,,,_xlfn.TEXTBEFORE(B8," ")) -> Brown | D8: =_xlfn.TEXTAFTER(B8,",",,,,_xlfn.TEXTAFTER(B8," ")) -> , Emma | E8: Brown, Emma | F8: Chat | G8: 27-32266 | I8: The customer was typing in all caps about an unapplied gift card. Emma matched the customer's defensive energy with cold, abrupt short phrases, escalating the tension. Customer asked for a new agent. Agent disconnected chat. | J8: First Contact Resolution
A9: 43934 | B9: Brown, Emma | C9: =_xlfn.TEXTBEFORE(B9,",",,,,_xlfn.TEXTBEFORE(B9," ")) -> Brown | D9: =_xlfn.TEXTAFTER(B9,",",,,,_xlfn.TEXTAFTER(B9," ")) -> Emma | E9: Brown, Emma | F9: Email | G9: 1258 | H9: 11156 | I9: A customer emailed about a missing item from their package. Emma responded within an hour, apologized sincerely, and immediately processed a expedited replacement shipment. | J9: Fillers/Punctuation
A10: 43935 | B10: Brown, Emma | C10: =_xlfn.TEXTBEFORE(B10,",",,,,_xlfn.TEXTBEFORE(B10," ")) -> Brown | D10: =_xlfn.TEXTAFTER(B10,",",,,,_xlfn.TEXTAFTER(B10," ")) -> Emma | E10: Brown, Emma | F10: Phone | G10: AD12542 | H10: 11163 | I10: A panicked customer called needing a dress changed to overnight shipping for a wedding. Emma intercepted the order in the warehouse management system just in time to upgrade the shipping method. However, she did not mention that the upgrade won't show for 24 hours. | J10: Dead Air, Fillers/Punctuation, First Contact Resolution
A11: 43924 | B11: Davis, Charlotte | C11: =_xlfn.TEXTBEFORE(B11,",",,,,_xlfn.TEXTBEFORE(B11," ")) -> Davis | D11: =_xlfn.TEXTAFTER(B11,",",,,,_xlfn.TEXTAFTER(B11," ")) -> Charlotte | E11: Davis, Charlotte | F11: Chat | G11: 27-32155 | I11: Customer chatted in to inquire if we have any shirts in an Orange color. Agent took a long time (2+ minutes) to research without getting back to the customer, but came back and provided a list of shirts that come in Orange. Some of these were discontinued, though. | J11: Dead Air, First Contact Resolution
A12: 43936 | B12: Davis, Charlotte | C12: =_xlfn.TEXTBEFORE(B12,",",,,,_xlfn.TEXTBEFORE(B12," ")) -> Davis | D12: =_xlfn.TEXTAFTER(B12,",",,,,_xlfn.TEXTAFTER(B12," ")) -> Charlotte | E12: Davis, Charlotte | F12: Phone | G12: AD12544 | H12: 11170 | I12: A customer called to praise a previous agent but stayed to order more items. Charlotte expertly cross-sold a matching accessory set, increasing the overall order value.
A13: 43924 | B13: Garcia, Ava | C13: =_xlfn.TEXTBEFORE(B13,",",,,,_xlfn.TEXTBEFORE(B13," ")) -> Garcia | D13: =_xlfn.TEXTAFTER(B13,",",,,,_xlfn.TEXTAFTER(B13," ")) -> Ava | E13: Garcia, Ava | F13: Chat | G13: 27-32154 | I13: Customer chatted in to see if we are hiring. Agent referred to company career site. | J13: Dead Air
A14: 43934 | B14: Gonzalez, Lucas | C14: =_xlfn.TEXTBEFORE(B14,",",,,,_xlfn.TEXTBEFORE(B14," ")) -> Gonzalez | D14: =_xlfn.TEXTAFTER(B14,",",,,,_xlfn.TEXTAFTER(B14," ")) -> Lucas | E14: Gonzalez, Lucas | F14: Email | G14: 1259 | H14: 11147 | I14: An email came in requesting a refund for a damaged dress. Lucas sent a generic macro response that completely ignored the attached photo proof, requiring the customer to email back in annoyance. | J14: First Contact Resolution
A15: 43937 | B15: Gonzalez, Lucas | C15: =_xlfn.TEXTBEFORE(B15,",",,,,_xlfn.TEXTBEFORE(B15," ")) -> Gonzalez | D15: =_xlfn.TEXTAFTER(B15,",",,,,_xlfn.TEXTAFTER(B15," ")) -> Lucas | E15: Gonzalez, Lucas | F15: Chat | G15: 27-32257 | H15: 11157 | I15: The customer asked a simple question about return windows. Lucas took over 4 minutes to type each basic response, leading the customer to ask if anyone was still there. | J15: Dead Air
A16: 43944 | B16: Gonzalez, Lucas | C16: =_xlfn.TEXTBEFORE(B16,",",,,,_xlfn.TEXTBEFORE(B16," ")) -> Gonzalez | D16: =_xlfn.TEXTAFTER(B16,",",,,,_xlfn.TEXTAFTER(B16," ")) -> Lucas | E16: Gonzalez, Lucas | F16: Chat | G16: 27-32153 | I16: Customer wants to know why they can't process their order. After asking several probing questions, the agent determined the customer was entering the wrong number as the CVV.
A17: 43926 | B17: Hernandez, Amelia | C17: =_xlfn.TEXTBEFORE(B17,",",,,,_xlfn.TEXTBEFORE(B17," ")) -> Hernandez | D17: =_xlfn.TEXTAFTER(B17,",",,,,_xlfn.TEXTAFTER(B17," ")) -> Amelia | E17: Hernandez, Amelia | F17: Email | G17: 1244 | H17: 11118 | I17: Customer emailed to ask where their order is - the tracking information isn't working for them. The agent replied with outdated template to provide tracking information and estimated delivery date. Accurate information was given, however. | J17: Scripting/Templates
A18: 43926 | B18: Hernandez, Benjamin | C18: =_xlfn.TEXTBEFORE(B18,",",,,,_xlfn.TEXTBEFORE(B18," ")) -> Hernandez | D18: =_xlfn.TEXTAFTER(B18,",",,,,_xlfn.TEXTAFTER(B18," ")) -> Benjamin | E18: Hernandez, Benjamin | F18: Email | G18: 1245 | H18: 11005 | I18: Customer wrote in to advise their zipper is broken after one use. The agent apologized, went over return process, and sent label.
A19: 43926 | B19: Hernandez, James | C19: =_xlfn.TEXTBEFORE(B19,",",,,,_xlfn.TEXTBEFORE(B19," ")) -> Hernandez | D19: =_xlfn.TEXTAFTER(B19,",",,,,_xlfn.TEXTAFTER(B19," ")) -> James | E19: Hernandez, James | F19: Email | G19: 1246 | H19: 11118 | I19: Customer replied to 1244 with thanks. The agent closed the conversation without replying.
A20: 43944 | B20: Jackson, Masonn | C20: =_xlfn.TEXTBEFORE(B20,",",,,,_xlfn.TEXTBEFORE(B20," ")) -> Jackson | D20: =_xlfn.TEXTAFTER(B20,",",,,,_xlfn.TEXTAFTER(B20," ")) -> Masonn | E20: Jackson, Mason | F20: Email | G20: 1247 | I20: Customer wrote in angrily because the coupon code they tried using was not working. The agent aplogized and asked them to reply with the code they were attempting to use. | J20: Scripting/Templates
A21: 43941 | B21: Jackson, Mason | C21: =_xlfn.TEXTBEFORE(B21,",",,,,_xlfn.TEXTBEFORE(B21," ")) -> Jackson | D21: =_xlfn.TEXTAFTER(B21,",",,,,_xlfn.TEXTAFTER(B21," ")) -> Mason | E21: Jackson, Mason | F21: Chat | G21: 27-32264 | I21: The customer asked if a specific material contained wool due to a severe allergy. Mason guessed "no" without checking the product spec sheet, creating a major safety risk. | J21: First Contact Resolution
A22: 43945 | B22: Johnson, Olivia | C22: =_xlfn.TEXTBEFORE(B22,",",,,,_xlfn.TEXTBEFORE(B22," ")) -> Johnson | D22: =_xlfn.TEXTAFTER(B22,",",,,,_xlfn.TEXTAFTER(B22," ")) -> Olivia | E22: Johnson, Olivia | F22: Phone | G22: AD12440 | I22: Customer called to ask about clothing that can be purchased in a variety of sizes: They are going on a family trip soon and want everyone to match. The agent was able to discuss all of the options that meet their requirements. The customer ended the call happy and advised they would make a purchase in the next few days. This contact does meet the criteria for the "Handle Time" note, but the agent was helpful to the customer and I do not believe this requires coaching. | J22: Handle Time
A23: 43927 | B23: Jones, Oliver | C23: =_xlfn.TEXTBEFORE(B23,",",,,,_xlfn.TEXTBEFORE(B23," ")) -> Jones | D23: =_xlfn.TEXTAFTER(B23,",",,,,_xlfn.TEXTAFTER(B23," ")) -> Oliver | E23: Jones, Oliver | F23: Phone | G23: AD12441 | H23: 11127 | I23: The customer called, irate because they felt like they were double-charged for their order. Agent attempted to explain authorization holds, but the customer kept cutting them off and hung up on the agent. | J23: Dead Air, Fillers/Punctuation
A24: 43927 | B24: Lee, Michael | C24: =_xlfn.TEXTBEFORE(B24,",",,,,_xlfn.TEXTBEFORE(B24," ")) -> Lee | D24: =_xlfn.TEXTAFTER(B24,",",,,,_xlfn.TEXTAFTER(B24," ")) -> Michael | E24: Lee, Michael | F24: Phone | G24: AD12442 | H24: 11120 | I24: Customer called because their order was marked as delivered, but they didn't recieve it. The agent checked the tracking, confirmed it was delivered over two days ago, and offered to reship overnight. The customer agreed.
A25: 43943 | B25: Lee, Michael | C25: =_xlfn.TEXTBEFORE(B25,",",,,,_xlfn.TEXTBEFORE(B25," ")) -> Lee | D25: =_xlfn.TEXTAFTER(B25,",",,,,_xlfn.TEXTAFTER(B25," ")) -> Michael | E25: Lee, Michael | F25: Chat | G25: 27-32267 | I25: A customer couldn't find where to enter a gift card code on a mobile browser. Michael took a quick screenshot, circled the field, and sent it over, resolving the issue instantly. | J25: Dead Air
A26: 43936 | B26: Lee, Michel | C26: =_xlfn.TEXTBEFORE(B26,",",,,,_xlfn.TEXTBEFORE(B26," ")) -> Lee | D26: =_xlfn.TEXTAFTER(B26,",",,,,_xlfn.TEXTAFTER(B26," ")) -> Michel | E26: Lee, Michael | F26: Phone | G26: AD12543 | H26: 11153 | I26: The customer called about a double-billing error. Michael put the customer on hold for over 10 minutes without checking back in, leading to a frustrated hang-up. | J26: Dead Air, First Contact Resolution, Handle Time
A27: 43927 | B27: Lee, Sophia | C27: =_xlfn.TEXTBEFORE(B27,",",,,,_xlfn.TEXTBEFORE(B27," ")) -> Lee | D27: =_xlfn.TEXTAFTER(B27,",",,,,_xlfn.TEXTAFTER(B27," ")) -> Sophia | E27: Lee, Sophia | F27: Phone | G27: AD12443 | H27: 11126 | I27: The customer called to report that their third package has arrived damaged. The agent checked the customer's history, saw repeated communications, and forwarded to a Specialist to handle. | J27: Dead Air
A28: 43928 | B28: Lopez, Isabella | C28: =_xlfn.TEXTBEFORE(B28,",",,,,_xlfn.TEXTBEFORE(B28," ")) -> Lopez | D28: =_xlfn.TEXTAFTER(B28,",",,,,_xlfn.TEXTAFTER(B28," ")) -> Isabella | E28: Lopez, Isabella | F28: Phone | G28: AD12444 | H28: 11150 | I28: The customer called in to try to place an order over the phone. The agent walked the customer through the ordering process. Agent thanked the customer for calling, but forgot to give the ending script. The customer did not hang up, so after a couple minutes the agent provided the disconnect script and ended the call. | J28: Scripting/Templates, Dead Air
A29: 43937 | B29: Lopez, Isabella | C29: =_xlfn.TEXTBEFORE(B29,",",,,,_xlfn.TEXTBEFORE(B29," ")) -> Lopez | D29: =_xlfn.TEXTAFTER(B29,",",,,,_xlfn.TEXTAFTER(B29," ")) -> Isabella | E29: Lopez, Isabella | F29: Chat | G29: 27-32258 | H29: 11151 | I29: The shopper’s tracking number hadn't updated in 5 days. Isabella quickly opened an investigation with the carrier and proactively set up a text alert to keep the customer updated. | J29: Handle Time
A30: 43942 | B30: Lopez, Isabella | C30: =_xlfn.TEXTBEFORE(B30,",",,,,_xlfn.TEXTBEFORE(B30," ")) -> Lopez | D30: =_xlfn.TEXTAFTER(B30,",",,,,_xlfn.TEXTAFTER(B30," ")) -> Isabella | E30: Lopez, Isabella | F30: Chat | G30: 27-32265 | H30: 11173 | I30: A customer received a pair of shoes with two different sizes. Isabella apologized for the warehouse mix-up, sent out the correct pair via express shipping, and told the customer to donate the mismatched pair. | J30: Fillers/Punctuation
A31: 43928 | B31: Martin, Camila | C31: =_xlfn.TEXTBEFORE(B31,",",,,,_xlfn.TEXTBEFORE(B31," ")) -> Martin | D31: =_xlfn.TEXTAFTER(B31,",",,,,_xlfn.TEXTAFTER(B31," ")) -> Camila | E31: Martin, Camila | F31: Phone | G31: AD12445 | H31: 11111 | I31: The customer contacted to initiate a return for a shirt that she didn't love - did not elaborate why. The agent explained the return process and provided the return label. | J31: Fillers/Punctuation
A32: 43949 | B32: Martin, Camila | C32: =_xlfn.TEXTBEFORE(B32,",",,,,_xlfn.TEXTBEFORE(B32," ")) -> Martin | D32: =_xlfn.TEXTAFTER(B32,",",,,,_xlfn.TEXTAFTER(B32," ")) -> Camila | E32: Martin, Camila | F32: Phone | G32: AD12446 | I32: The customer is calling back to talk to a Specialist regarding a complaint she wanted to make about the website. The agent put the customer on hold to transfer her over. | J32: Fillers/Punctuation
A33: 43936 | B33: Martinez, Bill | C33: =_xlfn.TEXTBEFORE(B33,",",,,,_xlfn.TEXTBEFORE(B33," ")) -> Martinez | D33: =_xlfn.TEXTAFTER(B33,",",,,,_xlfn.TEXTAFTER(B33," ")) -> Bill | E33: Martinez, Bill | F33: Phone | G33: AD12545 | I33: The customer called to report a broken website link on a major promotion page. Agentvalidated the issue, reported it immediately to IT, and manually applied the promo price for the caller. | J33: Handle Time
A34: 43948 | B34: Martinez, Bill | C34: =_xlfn.TEXTBEFORE(B34,",",,,,_xlfn.TEXTBEFORE(B34," ")) -> Martinez | D34: =_xlfn.TEXTAFTER(B34,",",,,,_xlfn.TEXTAFTER(B34," ")) -> Bill | E34: Martinez, Bill | F34: Chat | G34: 27-32259 | H34: 11205 | I34: A customer wanted to cancel an order placed 5 minutes prior. Bill acted instantly, canceling the order before it hit fulfillment and saving the customer return shipping fees. | J34: Scripting/Templates
A35: 43934 | B35: Martinez, Sophia | C35: =_xlfn.TEXTBEFORE(B35,",",,,,_xlfn.TEXTBEFORE(B35," ")) -> Martinez | D35: =_xlfn.TEXTAFTER(B35,",",,,,_xlfn.TEXTAFTER(B35," ")) -> Sophia | E35: Martinez, Sophia | F35: Email | G35: 1260 | H35: 11140 | I35: A bulk-order customer requested a custom invoice format for their corporate event clothing. Sophia coordinated with billing and delivered the exact breakdown requested. | J35: Handle Time
A36: 43935 | B36: Martinez, Sophia | C36: =_xlfn.TEXTBEFORE(B36,",",,,,_xlfn.TEXTBEFORE(B36," ")) -> Martinez | D36: =_xlfn.TEXTAFTER(B36,",",,,,_xlfn.TEXTAFTER(B36," ")) -> Sophia | E36: Martinez, Sophia | F36: Phone | G36: AD12540 | H36: 11102 | I36: The caller was highly irate about a major shipping delay. Sophia accidentally interrupted the customer mid-sentence to quote policy, which caused the customer to escalate the call to a manager. | J36: First Contact Resolution
A37: 43951 | B37: Martinez, Sophia | C37: =_xlfn.TEXTBEFORE(B37,",",,,,_xlfn.TEXTBEFORE(B37," ")) -> Martinez | D37: =_xlfn.TEXTAFTER(B37,",",,,,_xlfn.TEXTAFTER(B37," ")) -> Sophia | E37: Martinez, Sophia | F37: Phone | G37: AD12447 | I37: The customer called in to complain about previous service. They've called several times for various issues and has never had a happy experience. Most recently, they got a coupon they couldn't use and the replacement coupon didn't work. The agent seemed nervous and stammered a lot during the conversation, which made the customer escalate and ask for a Supervisor. Agent transferred to a Specialist. | J37: Fillers/Punctuation
A38: 43938 | B38: Miller, Elijah | C38: =_xlfn.TEXTBEFORE(B38,",",,,,_xlfn.TEXTBEFORE(B38," ")) -> Miller | D38: =_xlfn.TEXTAFTER(B38,",",,,,_xlfn.TEXTAFTER(B38," ")) -> Elijah | E38: Miller, Elijah | F38: Chat | G38: 27-32261 | H38: 11188 | I38: In a back-to-back chat, Elijah mixed up this customer's order details with a previous cancellation request, causing massive confusion for a customer who actually wanted to add an item. Customer had to chat in later to get clarification. | J38: Fillers/Punctuation, First Contact Resolution
A39: 43943 | B39: Miller, Elijah | C39: =_xlfn.TEXTBEFORE(B39,",",,,,_xlfn.TEXTBEFORE(B39," ")) -> Miller | D39: =_xlfn.TEXTAFTER(B39,",",,,,_xlfn.TEXTAFTER(B39," ")) -> Elijah | E39: Miller, Elijah | F39: Chat | G39: 27-32266 | I39: Elijah took over a transferred chat from Emma but failed to read the active conversation, asking the user "How can I help you today?" which caused the customer further upset, and they requested to speak to a supervisor. | J39: First Contact Resolution
A40: 43948 | B40: Miller, Elijah | C40: =_xlfn.TEXTBEFORE(B40,",",,,,_xlfn.TEXTBEFORE(B40," ")) -> Miller | D40: =_xlfn.TEXTAFTER(B40,",",,,,_xlfn.TEXTAFTER(B40," ")) -> Elijah | E40: Miller, Elijah | F40: Chat | G40: 27-32260 | H40: 11157 | I40: A customer complained that a shirt shrank significantly after one wash. Eli bluntly stated that because it was washed, it was no longer eligible for return, offering zero empathy or alternative solutions. | J40: First Contact Resolution
...

Sheet Counts
A1: Total Contacts | B1: =COUNT('April Cleaned Data'!A:A)-1 -> 50
A2: Yes | B2: =COUNTIF('April Cleaned Data'!J:J, "<>") -> 41
A3: No | B3: =B1-B2 -> 9
A8: Scripting/Templates | B8: =COUNTIF('April Cleaned Data'!J:J, "*"&A8&"*") -> 5
A9: Dead Air | B9: =COUNTIF('April Cleaned Data'!J:J, "*"&A9&"*") -> 12
A10: Fillers/Punctuation | B10: =COUNTIF('April Cleaned Data'!J:J, "*"&A10&"*") -> 11
A11: First Contact Resolution | B11: =COUNTIF('April Cleaned Data'!J:J, "*"&A11&"*") -> 16
A12: Handle Time | B12: =COUNTIF('April Cleaned Data'!J:J, "*"&A12&"*") -> 8

Sheet April Raw Data
A1: Date | B1: Agent Name | C1: Channel | D1: Contact ID | E1: Order# | F1: Original Call Driver | G1: Contact Notes | H1: Opportunities
A2: 43923 | B2: Henry Anderson | C2: Phone | D2: AD12434 | E2: 110025 | F2: Order Tracking | G2: Customer called to track order. Agent checked order, provided information of wrong order. | H2: Dead Air, First Contact Resolution
A3: 43923 | B3: Brown, Emma | C3: Phone | D3: AD12435 | F3: Product Inquiry | G3: Customer wanted to know if products were ethically sourced. Agent correctly provided information to sourcing.
A4: 43924 | B4: Davis, Charlotte | C4: Chat | D4: 27-32155 | F4: Product Inquiry | G4: Customer chatted in to inquire if we have any shirts in an Orange color. Agent took a long time (2+ minutes) to research without getting back to the customer, but came back and provided a list of shirts that come in Orange. Some of these were discontinued, though. | H4: Dead Air, First Contact Resolution
A5: 43924 | B5: Garcia, Ava | C5: Chat | D5: 27-32154 | F5: Other | G5: Customer chatted in to see if we are hiring. Agent referred to company career site. | H5: Dead Air
A6: 43926 | B6: Hernandez, Amelia | C6: Email | D6: 1244 | E6: 11118 | F6: Order Tracking | G6: Customer emailed to ask where their order is - the tracking information isn't working for them. The agent replied with outdated template to provide tracking information and estimated delivery date. Accurate information was given, however. | H6: Scripting/Templates
A7: 43926 | B7: Hernandez, Benjamin | C7: Email | D7: 1245 | E7: 11005 | F7: Damaged Product | G7: Customer wrote in to advise their zipper is broken after one use. The agent apologized, went over return process, and sent label.
A8: 43926 | B8: Hernandez, James | C8: Email | D8: 1246 | E8: 11118 | F8: Order Tracking | G8: Customer replied to 1244 with thanks. The agent closed the conversation without replying.
A9: 43927 | B9: Jones, Oliver | C9: Phone | D9: AD12441 | E9: 11127 | F9: Billing Issue | G9: The customer called, irate because they felt like they were double-charged for their order. Agent attempted to explain authorization holds, but the customer kept cutting them off and hung up on the agent. | H9: Dead Air, Fillers/Punctuation
A10: 43927 | B10: Lee, Michael | C10: Phone | D10: AD12442 | E10: 11120 | F10: Order Not Recieved | G10: Customer called because their order was marked as delivered, but they didn't recieve it. The agent checked the tracking, confirmed it was delivered over two days ago, and offered to reship overnight. The customer agreed.
A11: 43927 | B11: Lee, Sophia | C11: Phone | D11: AD12443 | E11: 11126 | F11: Damaged Product | G11: The customer called to report that their third package has arrived damaged. The agent checked the customer's history, saw repeated communications, and forwarded to a Specialist to handle. | H11: Dead Air
A12: 43928 | B12: Lopez, Isabella | C12: Phone | D12: AD12444 | E12: 11150 | F12: Place an Order | G12: The customer called in to try to place an order over the phone. The agent walked the customer through the ordering process. Agent thanked the customer for calling, but forgot to give the ending script. The customer did not hang up, so after a couple minutes the agent provided the disconnect script and ended the call. | H12: Scripting/Templates, Dead Air
A13: 43928 | B13: Martin, Camila | C13: Phone | D13: AD12445 | E13: 11111 | F13: Product Return | G13: The customer contacted to initiate a return for a shirt that she didn't love - did not elaborate why. The agent explained the return process and provided the return label. | H13: Fillers/Punctuation
A14: 43929 | B14: Millerr, Elijah | C14: Phone | D14: AD12448 | E14: 11149 | F14: Order Tracking | G14: Customer wanted to know where their order is. They can't check their email. The agent checked tracking and advised it was delivered. However, in watching the screen recording, the product isn't expected to be delivered until 4/15. | H14: First Contact Resolution
A15: 43929 | B15: Moore, Harper | C15: Phone | D15: AD12449 | E15: 11151 | F15: Address Issue | G15: Customer called because her address is incorrect on her order. She put the wrong house number on the address. The agent apologized, checked the tracking, noted it hasn't left the facility left, and issued a ticket to the carrier to update the address. | H15: Handle Time
A16: 43930 | B16: Rodriguez, William | C16: Phone | D16: AD12450 | E16: 11148 | F16: Order Tracking | G16: Standard WIZMO call. No notes for agent.
A17: 43930 | B17: Smith, Liam | C17: Phone | D17: AD12451 | E17: 11136 | F17: Order Not Recieved | G17: Customer didn't receive order, then found it on porch. No issues. No notes for agent.
A18: 43930 | B18: Taylor, Alexander | C18: Phone | D18: AD12452 | E18: 11152/11153 | F18: Billing Issue | G18: Customer about a double charge. Agent found two orders were shipped. Customer will return one when both arrive.
A19: 43931 | B19: Thomas, Evelyn | C19: Chat | D19: 27-32149 | E19: 11114 | F19: Product Return | G19: The customer reached out to exchange a sweater size. Evelyn processed the return label and applied a courtesy discount for a future purchase, leaving the customer thrilled. | H19: Dead Air, Handle Time
A20: 43932 | B20: Williams, Noah | C20: Chat | D20: 27-32148 | E20: 11163 | F20: Place an Order | G20: A customer needed help navigating the checkout page with a promo code. Noah patiently guided them click-by-click until the order went through successfully. | H20: Fillers/Punctuation
A21: 43933 | B21: Wilson, Mia | C21: Chat | D21: 27-32147 | F21: Website Issue | G21: The customer was frustrated that a clearance item sold out while in their cart. Mia gave rigid, scripted responses without offering alternative items, causing the customer to close the chat abruptly. | H21: First Contact Resolution
A22: 43933 | B22: Anderson, Henry | C22: Chat | D22: 27-32146 | F22: Product Inquiry | G22: A shopper asked for sizing recommendations for a specific brand of jeans. Henry looked up the precise measurements and helped them confidently pick the right size. | H22: Handle Time
A23: 43933 | B23: Anderson, Henry | C23: Chat | D23: 27-32145 | E23: 11155 | F23: Address Issue | G23: A customer was disconnect-looping and frustrated. Henry didn't read the prior notes from the immediate previous chat and made the customer repeat their shipping address issue all over again. Customer ended up disconnecting again. | H23: First Contact Resolution
A24: 43934 | B24: Brown, Emma | C24: Email | D24: 1258 | E24: 11156 | F24: Short-shipped | G24: A customer emailed about a missing item from their package. Emma responded within an hour, apologized sincerely, and immediately processed a expedited replacement shipment. | H24: Fillers/Punctuation
A25: 43934 | B25: Gonzalez, Lucas | C25: Email | D25: 1259 | E25: 11147 | F25: Damaged Product | G25: An email came in requesting a refund for a damaged dress. Lucas sent a generic macro response that completely ignored the attached photo proof, requiring the customer to email back in annoyance. | H25: First Contact Resolution
A26: 43934 | B26: Martinez, Sophia | C26: Email | D26: 1260 | E26: 11140 | F26: Billing Issue | G26: A bulk-order customer requested a custom invoice format for their corporate event clothing. Sophia coordinated with billing and delivered the exact breakdown requested. | H26: Handle Time
A27: 43935 | B27: Martinez, Sophia | C27: Phone | D27: AD12540 | E27: 11102 | F27: Order Tracking | G27: The caller was highly irate about a major shipping delay. Sophia accidentally interrupted the customer mid-sentence to quote policy, which caused the customer to escalate the call to a manager. | H27: First Contact Resolution
A28: 43935 | B28: Anderson, Henry | C28: Phone | D28: AD12541 | E28: 11146 | F28: Product Return | G28: An elderly customer called confused about how to initiate an online return. Henry remained incredibly warm and patient, staying on the line until the return label was successfully printed.
A29: 43935 | B29: Brown, Emma | C29: Phone | D29: AD12542 | E29: 11163 | F29: Order Tracking | G29: A panicked customer called needing a dress changed to overnight shipping for a wedding. Emma intercepted the order in the warehouse management system just in time to upgrade the shipping method. However, she did not mention that the upgrade won't show for 24 hours. | H29: Dead Air, Fillers/Punctuation, First Contact Resolution
A30: 43936 | B30: Lee, Michel | C30: Phone | D30: AD12543 | E30: 11153 | F30: Billing Issue | G30: The customer called about a double-billing error. Michael put the customer on hold for over 10 minutes without checking back in, leading to a frustrated hang-up. | H30: Dead Air, First Contact Resolution, Handle Time
A31: 43936 | B31: Davis, Charlotte | C31: Phone | D31: AD12544 | E31: 11170 | F31: Place an Order | G31: A customer called to praise a previous agent but stayed to order more items. Charlotte expertly cross-sold a matching accessory set, increasing the overall order value.
A32: 43936 | B32: Martinez, Bill | C32: Phone | D32: AD12545 | F32: Website Issue | G32: The customer called to report a broken website link on a major promotion page. Agentvalidated the issue, reported it immediately to IT, and manually applied the promo price for the caller. | H32: Handle Time
A33: 43936 | B33: Smith, Liam | C33: Phone | D33: AD12546 | E33: 11115 | F33: Billing Issue | G33: The caller had a thick accent and was struggling to explain a refund issue. Liam showed visible impatience and spoke too fast, making the customer feel unwelcome and dismissed. | H33: First Contact Resolution
A34: 43937 | B34: Thomas, Evelyn | C34: Chat | D34: 27-32256 | F34: Product Inquiry | G34: A customer was looking for a specific outfit style for a family photoshoot. Evelyn acted as a personal stylist, dropping links to coordinating pieces that the customer immediately bought. | H34: Scripting/Templates
A35: 43937 | B35: Gonzalez, Lucas | C35: Chat | D35: 27-32257 | E35: 11157 | F35: Product Return | G35: The customer asked a simple question about return windows. Lucas took over 4 minutes to type each basic response, leading the customer to ask if anyone was still there. | H35: Dead Air
A36: 43937 | B36: Lopez, Isabella | C36: Chat | D36: 27-32258 | E36: 11151 | F36: Order Tracking | G36: The shopper’s tracking number hadn't updated in 5 days. Isabella quickly opened an investigation with the carrier and proactively set up a text alert to keep the customer updated. | H36: Handle Time
A37: 43938 | B37: Miller, Elijah | C37: Chat | D37: 27-32261 | E37: 11188 | F37: Update Order | G37: In a back-to-back chat, Elijah mixed up this customer's order details with a previous cancellation request, causing massive confusion for a customer who actually wanted to add an item. Customer had to chat in later to get clarification. | H37: Fillers/Punctuation, First Contact Resolution
A38: 43941 | B38: Anderson, Henry | C38: Chat | D38: 27-32263 | E38: 11163 | F38: Order Not Recieved | G38: The customer's package was stolen from their porch. Henry expressed genuine empathy and authorized a one-time courtesy replacement order to be shipped to a secure pickup location. | H38: Fillers/Punctuation
